Workbook

Sheet orders
A1: order_id | B1: date | C1: customer_id | D1: product_id | E1: qty | F1: Customer Name | G1: Product Name | H1: Price | I1: Total Price
A2: 1125 | B2: 44958 | C2: 11 | D2: 704 | E2: 6 | F2: =VLOOKUP(C2,customers!A:B,2,FALSE) -> AnthoNY | G2: =INDEX(products!B:B, MATCH(D2, products!A:A, 0)) -> Eggs | H2: =VLOOKUP(D2,products!A:C,3,FALSE) -> 155 | I2: =orders[[#This Row],[qty]]*orders[[#This Row],[Price]] -> 930
A3: 1127 | B3: 44958 | C3: 19 | D3: 392 | E3: 2 | F3: =VLOOKUP(C3,customers!A:B,2,FALSE) -> ahmeD | G3: =INDEX(products!B:B, MATCH(D3, products!A:A, 0)) -> Yogurt | H3: =VLOOKUP(D3,products!A:C,3,FALSE) -> 118 | I3: =orders[[#This Row],[qty]]*orders[[#This Row],[Price]] -> 236
A4: 1152 | B4: 44958 | C4: 14 | D4: 646 | E4: 7 | F4: =VLOOKUP(C4,customers!A:B,2,FALSE) -> RavI | G4: =INDEX(products!B:B, MATCH(D4, products!A:A, 0)) -> Apple | H4: =VLOOKUP(D4,products!A:C,3,FALSE) -> 52 | I4: =orders[[#This Row],[qty]]*orders[[#This Row],[Price]] -> 364
A5: 1153 | B5: 44958 | C5: 35 | D5: 294 | E5: 9 | F5: =VLOOKUP(C5,customers!A:B,2,FALSE) -> MiKe | G5: =INDEX(products!B:B, MATCH(D5, products!A:A, 0)) -> Rice | H5: =VLOOKUP(D5,products!A:C,3,FALSE) -> 130 | I5: =orders[[#This Row],[qty]]*orders[[#This Row],[Price]] -> 1170
A6: 1161 | B6: 44958 | C6: 35 | D6: 651 | E6: 6 | F6: =VLOOKUP(C6,customers!A:B,2,FALSE) -> MiKe | G6: =INDEX(products!B:B, MATCH(D6, products!A:A, 0)) -> Banana | H6: =VLOOKUP(D6,products!A:C,3,FALSE) -> 89 | I6: =orders[[#This Row],[qty]]*orders[[#This Row],[Price]] -> 534
A7: 1163 | B7: 44959 | C7: 50 | D7: 646 | E7: 4 | F7: =VLOOKUP(C7,customers!A:B,2,FALSE) -> BRuce | G7: =INDEX(products!B:B, MATCH(D7, products!A:A, 0)) -> Apple | H7: =VLOOKUP(D7,products!A:C,3,FALSE) -> 52 | I7: =orders[[#This Row],[qty]]*orders[[#This Row],[Price]] -> 208
A8: 1167 | B8: 44959 | C8: 35 | D8: 739 | E8: 9 | F8: =VLOOKUP(C8,customers!A:B,2,FALSE) -> MiKe | G8: =INDEX(products!B:B, MATCH(D8, products!A:A, 0)) -> Donut | H8: =VLOOKUP(D8,products!A:C,3,FALSE) -> 452 | I8: =orders[[#This Row],[qty]]*orders[[#This Row],[Price]] -> 4068
A9: 1167 | B9: 44959 | C9: 35 | D9: 739 | E9: 8 | F9: =VLOOKUP(C9,customers!A:B,2,FALSE) -> MiKe | G9: =INDEX(products!B:B, MATCH(D9, products!A:A, 0)) -> Donut | H9: =VLOOKUP(D9,products!A:C,3,FALSE) -> 452 | I9: =orders[[#This Row],[qty]]*orders[[#This Row],[Price]] -> 3616
A10: 1176 | B10: 44959 | C10: 11 | D10: 628 | E10: 5 | F10: =VLOOKUP(C10,customers!A:B,2,FALSE) -> AnthoNY | G10: =INDEX(products!B:B, MATCH(D10, products!A:A, 0)) -> Fish | H10: =VLOOKUP(D10,products!A:C,3,FALSE) -> 206 | I10: =orders[[#This Row],[qty]]*orders[[#This Row],[Price]] -> 1030
A11: 1183 | B11: 44959 | C11: 21 | D11: 163 | E11: 7 | F11: =VLOOKUP(C11,customers!A:B,2,FALSE) -> Lisa | G11: =INDEX(products!B:B, MATCH(D11, products!A:A, 0)) -> Grape Juice | H11: =VLOOKUP(D11,products!A:C,3,FALSE) -> 152 | I11: =orders[[#This Row],[qty]]*orders[[#This Row],[Price]] -> 1064
A12: 1187 | B12: 44959 | C12: 19 | D12: 594 | E12: 6 | F12: =VLOOKUP(C12,customers!A:B,2,FALSE) -> ahmeD | G12: =INDEX(products!B:B, MATCH(D12, products!A:A, 0)) -> Chicken | H12: =VLOOKUP(D12,products!A:C,3,FALSE) -> 335 | I12: =orders[[#This Row],[qty]]*orders[[#This Row],[Price]] -> 2010
A13: 1193 | B13: 44960 | C13: 34 | D13: 651 | E13: 2 | F13: =VLOOKUP(C13,customers!A:B,2,FALSE) -> JaY | G13: =INDEX(products!B:B, MATCH(D13, products!A:A, 0)) -> Banana | H13: =VLOOKUP(D13,products!A:C,3,FALSE) -> 89 | I13: =orders[[#This Row],[qty]]*orders[[#This Row],[Price]] -> 178
... A15: 1195 | B15: 44960 | C15: 29 | D15: 739 | E15: 3 | F15: =VLOOKUP(C15,customers!A:B,2,FALSE) -> johN | G15: =INDEX(products!B:B, MATCH(D15, products!A:A, 0)) -> Donut | H15: =VLOOKUP(D15,products!A:C,3,FALSE) -> 452 | I15: =orders[[#This Row],[qty]]*orders[[#This Row],[Price]] -> 1356
A16: 1199 | B16: 44960 | C16: 35 | D16: 797 | F16: =VLOOKUP(C16,customers!A:B,2,FALSE) -> MiKe | G16: =INDEX(products!B:B, MATCH(D16, products!A:A, 0)) -> Cheese | H16: =VLOOKUP(D16,products!A:C,3,FALSE) -> 402 | I16: =orders[[#This Row],[qty]]*orders[[#This Row],[Price]] -> 0
A17: 1200 | B17: 44960 | C17: 79 | D17: 521 | E17: 3 | F17: =VLOOKUP(C17,customers!A:B,2,FALSE) -> TiM | G17: =INDEX(products!B:B, MATCH(D17, products!A:A, 0)) -> Carrot | H17: =VLOOKUP(D17,products!A:C,3,FALSE) -> 41 | I17: =orders[[#This Row],[qty]]*orders[[#This Row],[Price]] -> 123
A18: 1206 | B18: 44961 | C18: 11 | D18: 886 | F18: =VLOOKUP(C18,customers!A:B,2,FALSE) -> AnthoNY | G18: =INDEX(products!B:B, MATCH(D18, products!A:A, 0)) -> Avocado | H18: =VLOOKUP(D18,products!A:C,3,FALSE) -> 322 | I18: =orders[[#This Row],[qty]]*orders[[#This Row],[Price]] -> 0
A19: 1211 | B19: 44961 | C19: 79 | D19: 646 | E19: 7 | F19: =VLOOKUP(C19,customers!A:B,2,FALSE) -> TiM | G19: =INDEX(products!B:B, MATCH(D19, products!A:A, 0)) -> Apple | H19: =VLOOKUP(D19,products!A:C,3,FALSE) -> 52 | I19: =orders[[#This Row],[qty]]*orders[[#This Row],[Price]] -> 364
A20: 1213 | B20: 44961 | C20: 29 | D20: 328 | E20: 10 | F20: =VLOOKUP(C20,customers!A:B,2,FALSE) -> johN | G20: =INDEX(products!B:B, MATCH(D20, products!A:A, 0)) -> Pasta | H20: =VLOOKUP(D20,products!A:C,3,FALSE) -> 131 | I20: =orders[[#This Row],[qty]]*orders[[#This Row],[Price]] -> 1310
A21: 1215 | B21: 44961 | C21: 21 | D21: 811 | E21: 3 | F21: =VLOOKUP(C21,customers!A:B,2,FALSE) -> Lisa | G21: =INDEX(products!B:B, MATCH(D21, products!A:A, 0)) -> Celery | H21: =VLOOKUP(D21,products!A:C,3,FALSE) -> 16 | I21: =orders[[#This Row],[qty]]*orders[[#This Row],[Price]] -> 48
A22: 1227 | B22: 44961 | C22: 50 | D22: 704 | E22: 5 | F22: =VLOOKUP(C22,customers!A:B,2,FALSE) -> BRuce | G22: =INDEX(products!B:B, MATCH(D22, products!A:A, 0)) -> Eggs | H22: =VLOOKUP(D22,products!A:C,3,FALSE) -> 155 | I22: =orders[[#This Row],[qty]]*orders[[#This Row],[Price]] -> 775
A23: 1233 | B23: 44962 | C23: 79 | D23: 328 | E23: 10 | F23: =VLOOKUP(C23,customers!A:B,2,FALSE) -> TiM | G23: =INDEX(products!B:B, MATCH(D23, products!A:A, 0)) -> Pasta | H23: =VLOOKUP(D23,products!A:C,3,FALSE) -> 131 | I23: =orders[[#This Row],[qty]]*orders[[#This Row],[Price]] -> 1310
A24: 1235 | B24: 44962 | C24: 14 | D24: 163 | E24: 10 | F24: =VLOOKUP(C24,customers!A:B,2,FALSE) -> RavI | G24: =INDEX(products!B:B, MATCH(D24, products!A:A, 0)) -> Grape Juice | H24: =VLOOKUP(D24,products!A:C,3,FALSE) -> 152 | I24: =orders[[#This Row],[qty]]*orders[[#This Row],[Price]] -> 1520
A25: 1255 | B25: 44962 | C25: 50 | D25: 521 | E25: 2 | F25: =VLOOKUP(C25,customers!A:B,2,FALSE) -> BRuce | G25: =INDEX(products!B:B, MATCH(D25, products!A:A, 0)) -> Carrot | H25: =VLOOKUP(D25,products!A:C,3,FALSE) -> 41 | I25: =orders[[#This Row],[qty]]*orders[[#This Row],[Price]] -> 82
A26: 1257 | B26: 44962 | C26: 11 | D26: 590 | E26: 8 | F26: =VLOOKUP(C26,customers!A:B,2,FALSE) -> AnthoNY | G26: =INDEX(products!B:B, MATCH(D26, products!A:A, 0)) -> French Fries | H26: =VLOOKUP(D26,products!A:C,3,FALSE) -> 365 | I26: =orders[[#This Row],[qty]]*orders[[#This Row],[Price]] -> 2920
A27: 1258 | B27: 44962 | C27: 34 | D27: 704 | E27: 4 | F27: =VLOOKUP(C27,customers!A:B,2,FALSE) -> JaY | G27: =INDEX(products!B:B, MATCH(D27, products!A:A, 0)) -> Eggs | H27: =VLOOKUP(D27,products!A:C,3,FALSE) -> 155 | I27: =orders[[#This Row],[qty]]*orders[[#This Row],[Price]] -> 620
A28: 1273 | B28: 44963 | C28: 50 | D28: 886 | E28: 3 | F28: =VLOOKUP(C28,customers!A:B,2,FALSE) -> BRuce | G28: =INDEX(products!B:B, MATCH(D28, products!A:A, 0)) -> Avocado | H28: =VLOOKUP(D28,products!A:C,3,FALSE) -> 322 | I28: =orders[[#This Row],[qty]]*orders[[#This Row],[Price]] -> 966
A29: 1277 | B29: 44963 | C29: 34 | D29: 704 | E29: 6 | F29: =VLOOKUP(C29,customers!A:B,2,FALSE) -> JaY | G29: =INDEX(products!B:B, MATCH(D29, products!A:A, 0)) -> Eggs | H29: =VLOOKUP(D29,products!A:C,3,FALSE) -> 155 | I29: =orders[[#This Row],[qty]]*orders[[#This Row],[Price]] -> 930
A30: 1289 | B30: 44963 | C30: 19 | D30: 811 | E30: 6 | F30: =VLOOKUP(C30,customers!A:B,2,FALSE) -> ahmeD | G30: =INDEX(products!B:B, MATCH(D30, products!A:A, 0)) -> Celery | H30: =VLOOKUP(D30,products!A:C,3,FALSE) -> 16 | I30: =orders[[#This Row],[qty]]*orders[[#This Row],[Price]] -> 96
... A38: 1302 | B38: 44964 | C38: 34 | D38: 328 | E38: 3 | F38: =VLOOKUP(C38,customers!A:B,2,FALSE) -> JaY | G38: =INDEX(products!B:B, MATCH(D38, products!A:A, 0)) -> Pasta | H38: =VLOOKUP(D38,products!A:C,3,FALSE) -> 131 | I38: =orders[[#This Row],[qty]]*orders[[#This Row],[Price]] -> 393
A39: 1309 | B39: 44965 | C39: 34 | D39: 163 | F39: =VLOOKUP(C39,customers!A:B,2,FALSE) -> JaY | G39: =INDEX(products!B:B, MATCH(D39, products!A:A, 0)) -> Grape Juice | H39: =VLOOKUP(D39,products!A:C,3,FALSE) -> 152 | I39: =orders[[#This Row],[qty]]*orders[[#This Row],[Price]] -> 0
A40: 1310 | B40: 44965 | C40: 79 | D40: 484 | E40: 3 | F40: =VLOOKUP(C40,customers!A:B,2,FALSE) -> TiM | G40: =INDEX(products!B:B, MATCH(D40, products!A:A, 0)) -> Hamburger | H40: =VLOOKUP(D40,products!A:C,3,FALSE) -> 250 | I40: =orders[[#This Row],[qty]]*orders[[#This Row],[Price]] -> 750
A41: 1318 | B41: 44965 | C41: 29 | D41: 794 | E41: 3 | F41: =VLOOKUP(C41,customers!A:B,2,FALSE) -> johN | G41: =INDEX(products!B:B, MATCH(D41, products!A:A, 0)) -> Grilled Cheese | H41: =VLOOKUP(D41,products!A:C,3,FALSE) -> 440 | I41: =orders[[#This Row],[qty]]*orders[[#This Row],[Price]] -> 1320
A42: 1319 | B42: 44965 | C42: 14 | D42: 521 | E42: 6 | F42: =VLOOKUP(C42,customers!A:B,2,FALSE) -> RavI | G42: =INDEX(products!B:B, MATCH(D42, products!A:A, 0)) -> Carrot | H42: =VLOOKUP(D42,products!A:C,3,FALSE) -> 41 | I42: =orders[[#This Row],[qty]]*orders[[#This Row],[Price]] -> 246
A43: 1321 | B43: 44965 | C43: 21 | D43: 594 | E43: 7 | F43: =VLOOKUP(C43,customers!A:B,2,FALSE) -> Lisa | G43: =INDEX(products!B:B, MATCH(D43, products!A:A, 0)) -> Chicken | H43: =VLOOKUP(D43,products!A:C,3,FALSE) -> 335 | I43: =orders[[#This Row],[qty]]*orders[[#This Row],[Price]] -> 2345
A44: 1323 | B44: 44966 | C44: 79 | D44: 646 | E44: 9 | F44: =VLOOKUP(C44,customers!A:B,2,FALSE) -> TiM | G44: =INDEX(products!B:B, MATCH(D44, products!A:A, 0)) -> Apple | H44: =VLOOKUP(D44,products!A:C,3,FALSE) -> 52 | I44: =orders[[#This Row],[qty]]*orders[[#This Row],[Price]] -> 468
A45: 1324 | B45: 44966 | C45: 19 | D45: 594 | E45: 8 | F45: =VLOOKUP(C45,customers!A:B,2,FALSE) -> ahmeD | G45: =INDEX(products!B:B, MATCH(D45, products!A:A, 0)) -> Chicken | H45: =VLOOKUP(D45,products!A:C,3,FALSE) -> 335 | I45: =orders[[#This Row],[qty]]*orders[[#This Row],[Price]] -> 2680
A46: 1327 | B46: 44966 | C46: 50 | D46: 392 | E46: 9 | F46: =VLOOKUP(C46,customers!A:B,2,FALSE) -> BRuce | G46: =INDEX(products!B:B, MATCH(D46, products!A:A, 0)) -> Yogurt | H46: =VLOOKUP(D46,products!A:C,3,FALSE) -> 118 | I46: =orders[[#This Row],[qty]]*orders[[#This Row],[Price]] -> 1062
A47: 1330 | B47: 44966 | C47: 29 | D47: 804 | E47: 10 | F47: =VLOOKUP(C47,customers!A:B,2,FALSE) -> johN | G47: =INDEX(products!B:B, MATCH(D47, products!A:A, 0)) -> Broccoli | H47: =VLOOKUP(D47,products!A:C,3,FALSE) -> 34 | I47: =orders[[#This Row],[qty]]*orders[[#This Row],[Price]] -> 340
A48: 1335 | B48: 44966 | C48: 34 | D48: 811 | E48: 6 | F48: =VLOOKUP(C48,customers!A:B,2,FALSE) -> JaY | G48: =INDEX(products!B:B, MATCH(D48, products!A:A, 0)) -> Celery | H48: =VLOOKUP(D48,products!A:C,3,FALSE) -> 16 | I48: =orders[[#This Row],[qty]]*orders[[#This Row],[Price]] -> 96
...

Sheet products
A1: product_id | B1: product_name | C1: calories | D1: protein | E1: carbs | F1: fat | G1: price (in INR)
A2: 646 | B2: Apple | C2: 52 | D2: 0.26 | E2: 13.8 | F2: 0.17 | G2: ₹200
A3: 651 | B3: Banana | C3: 89 | D3: 1.09 | E3: 22.8 | F3: 0.33 | G3: ₹80
A4: 886 | B4: Avocado | C4: 322 | D4: 4.02 | E4: 17.15 | F4: 29.47 | G4: ₹100
A5: 804 | B5: Broccoli | C5: 34 | D5: 2.82 | E5: 6.64 | F5: 0.37 | G5: ₹30
A6: 594 | B6: Chicken | C6: 335 | D6: 31.02 | E6: 0 | F6: 23.11 | G6: ₹250
A7: 628 | B7: Fish | C7: 206 | D7: 20.26 | E7: 0 | F7: 13.92 | G7: ₹120
A8: 294 | B8: Rice | C8: 130 | D8: 2.69 | E8: 28.73 | F8: 0.28 | G8: ₹80
A9: 328 | B9: Pasta | C9: 131 | D9: 5.47 | E9: 25.77 | F9: 1.03 | G9: ₹60
A10: 521 | B10: Carrot | C10: 41 | D10: 0.93 | E10: 9.58 | F10: 0.24 | G10: ₹40
A11: 811 | B11: Celery | C11: 16 | D11: 0.69 | E11: 3.06 | F11: 0.17 | G11: ₹50
A12: 797 | B12: Cheese | C12: 402 | D12: 25.09 | E12: 3.09 | F12: 33.82 | G12: ₹80
A13: 862 | B13: Chocolate Cake | C13: 452 | D13: 3.75 | E13: 44.61 | F13: 29.11 | G13: ₹200
... A21: 484 | B21: Hamburger | C21: 250 | D21: 13.29 | E21: 17.32 | F21: 14.62 | G21: ₹70

Sheet customers
A1: customer_id | B1: customer
A2: 34 | B2: JaY
A3: 29 | B3: johN
A4: 79 | B4: TiM
A5: 14 | B5: RavI
A6: 21 | B6: Lisa
A7: 19 | B7: ahmeD
A8: 35 | B8: MiKe
A9: 50 | B9: BRuce
A10: 35 | B10: MahESh
A11: 11 | B11: AnthoNY
